This Go program demonstrates how to use the `errgroup.Group` from the `golang.org/x/sync/errgroup` package to manage concurrent tasks (goroutines) and handle errors in those tasks.

### Key Concepts and Rules:

1. **`errgroup.Group`**:
   - The `errgroup.Group` is used to manage multiple goroutines concurrently. It helps you handle errors from multiple goroutines, and it ensures that only the first error encountered is returned.
   - The `Go` method is used to start a new goroutine, and it associates a function with the group. This function should return an error (or `nil`).
   - The `Wait` method waits for all goroutines to complete. If any goroutine returns an error, `Wait` returns the first error it encountered; otherwise, it returns `nil`.

2. **Concurrency with `Go`**:
   - The `Go` method allows you to execute multiple functions concurrently in separate goroutines. You can launch as many concurrent tasks as needed.
   - Each goroutine can independently return an error, which will be collected by the `errgroup`.

3. **Error Handling**:
   - If any goroutine returns an error, the error will be propagated to the caller via the `Wait` method. If no errors occur, `Wait` returns `nil`.
   - `errgroup` guarantees that only the first error encountered is returned, so if multiple goroutines fail, only the first error will be reported.

4. **`Wait()`**:
   - The `Wait()` method blocks until all goroutines have completed.
   - It returns the first error encountered (if any). If no errors occur, it returns `nil`.
   - The program will not wait for the other goroutines if one has already returned an error; it immediately returns the first error.

### Explanation of the Code:

```go
func main() {
	if err := work(); err != nil {
		fmt.Println(err) // something bad has happened
	}
}
```
- In the `main` function, we call the `work()` function. If an error is returned from `work()`, we print it out. The message printed will depend on the result of the `work()` function.

```go
func work() error {
	var eg errgroup.Group
```
- The `work()` function begins by creating a new `errgroup.Group`, `eg`, which will manage the goroutines.

```go
	eg.Go(func() error {
		// Выполняем какую-то операцию, завершившуюся с ошибкой.
		// ...
		return errors.New("something bad has happened")
	})
```
- The first goroutine is started using `eg.Go()`. This goroutine simulates some operation that results in an error. It returns the error `"something bad has happened"`.
- The `Go` method will execute this function concurrently with other functions.

```go
	eg.Go(func() error {
		// Выполняем какую-то операцию, завершившуюся без ошибки.
		// ...
		return nil
	})
```
- The second goroutine is started using `eg.Go()`. This goroutine simulates an operation that does not produce an error and returns `nil`.

```go
	// Дожидаемся окончания работ.
	// Возвращаем ошибку от любой из операций (если ошибка произошла).
	return eg.Wait()
}
```
- `eg.Wait()` blocks until both goroutines have completed. Since the first goroutine returned an error (`"something bad has happened"`), `Wait` will immediately return that error and ignore the result of the second goroutine (which returned `nil`).

- The `work()` function returns the error returned by `eg.Wait()` to the caller (in this case, the `main` function).

### Error Handling Flow:

1. **First Goroutine**: The first goroutine performs an operation that results in an error (`"something bad has happened"`), and it returns this error.
2. **Second Goroutine**: The second goroutine completes without error (returns `nil`), but it does not affect the overall result because the `errgroup` only cares about the **first** error encountered.
3. **`Wait()` Method**: When `Wait()` is called, it blocks until both goroutines finish. It returns the first error encountered, which is `"something bad has happened"`.
4. **Return to `main`**: The `work()` function returns the error `"something bad has happened"`, which is then printed in the `main` function.

### Output:

The output of the program will be:
```
something bad has happened
```

### Conclusion:

- The key point here is the behavior of `errgroup.Group`. It allows you to run multiple goroutines concurrently and ensures that the first error encountered (if any) is propagated back to the caller. Once an error is returned, `Wait()` stops waiting for other goroutines and returns that error.
- The second goroutine's result (`nil`) is ignored because the first goroutine returned an error.