This Go program demonstrates how to handle multiple errors efficiently, using `multierr` from the `go.uber.org/multierr` package. The program primarily illustrates how to manage errors that arise from file processing and resource (like `CloserMock`) management, as well as how to combine and append errors when they occur. Here's a detailed explanation of the key rules and concepts in the code:

### 1. **Using `multierr.AppendInvoke` for Error Handling**

`multierr.AppendInvoke` is used in this code to manage errors that occur in the `defer` statements or when closing resources. It ensures that errors are properly captured and propagated.

### Process Breakdown:

#### 1.1 **processFile function**
```go
func processFile(path string) (err error) {
    f, err := os.Open(path)
    if err != nil {
        return fmt.Errorf("open file: %v", err)
    }
    defer multierr.AppendInvoke(&err, multierr.Close(f))

    scanner := bufio.NewScanner(f)
    defer multierr.AppendInvoke(&err, multierr.Invoke(scanner.Err))

    for scanner.Scan() {
        fmt.Println(scanner.Text())
    }
    return nil
}
```

- **Opening the file**: The program tries to open the file specified by the `path`. If there's an error opening the file (`os.Open`), that error is returned with additional context: `"open file: %v"`.
- **Deferring file close with error handling**: 
    ```go
    defer multierr.AppendInvoke(&err, multierr.Close(f))
    ```
    This line ensures that the file is properly closed after the function execution. If closing the file (`f.Close()`) results in an error, `multierr.AppendInvoke` appends that error to the `err` variable, which is returned at the end of the function.
  
- **Using a scanner to read the file**: 
    ```go
    scanner := bufio.NewScanner(f)
    defer multierr.AppendInvoke(&err, multierr.Invoke(scanner.Err))
    ```
    The `scanner` reads the file line by line. If there’s an error while scanning (`scanner.Err()`), that error is also captured using `multierr.AppendInvoke`.

- **Return error**: The function ends by returning any accumulated errors, if they exist.

#### 1.2 **Using `multierr.AppendInvoke` for Closing and Error Propagation**

```go
func processCloserMock() (err error) {
    defer multierr.AppendInvoke(&err, multierr.Close(CloserMock{}))
    return nil
}
```

- **CloserMock** is a mock type that implements `io.Closer` with a `Close()` method that always returns an error (`"close error"`).
- **Deferring the close**: `multierr.AppendInvoke(&err, multierr.Close(CloserMock{}))` ensures that the `Close()` method is called when the function exits. If the `Close()` method returns an error, it gets appended to the `err` variable.

```go
func processCloserMockWithError() (err error) {
    defer multierr.AppendInvoke(&err, multierr.Close(CloserMock{}))
    return errors.New("process error")
}
```

- This function simulates a scenario where an error occurs during the process itself (a "process error").
- The `multierr.AppendInvoke` ensures that, in addition to the `process error`, the error from `CloserMock.Close()` (which is `"close error"`) is also captured and returned.

### 2. **Handling Multiple Errors**

The key function in this program is `multierr.AppendInvoke`, which is used to append errors to an already-existing error variable (`err`). This way, multiple errors can be captured and returned together. 

The `multierr` package is useful when you want to accumulate errors from different sources or functions, especially when you need to ensure resources are cleaned up properly (e.g., file closing, network connections, etc.) even when an earlier operation has already failed.

#### 2.1 **How `multierr.AppendInvoke` Works**
- **Append**: `multierr.AppendInvoke` adds an error to the given error variable (`err`), ensuring that the error is recorded without overwriting the existing error value. It’s especially useful in `defer` statements.
- **Invoke**: `multierr.Invoke` calls a function and appends the returned error to the given error variable, allowing you to capture errors from function calls or other operations.

### 3. **CloserMock Implementation**

The program also defines a mock `io.Closer` implementation for testing purposes.

```go
var _ io.Closer = CloserMock{}

type CloserMock struct{}

func (c CloserMock) Close() error {
    return errors.New("close error")
}
```

- **CloserMock** implements the `io.Closer` interface by providing a `Close()` method that always returns the error `"close error"`.
- This mock is used in `processCloserMock` and `processCloserMockWithError` to simulate closing a resource that results in an error.

### 4. **Main Function and Output**

The `main` function runs the three processing functions and prints the resulting errors:

```go
if err := processFile("/etc/hosts"); err != nil {
    fmt.Printf("%v\n", err)
}

if err := processCloserMock(); err != nil {
    fmt.Printf("%v\n", err)
}

if err := processCloserMockWithError(); err != nil {
    fmt.Printf("%v\n", err)
}
```

- **File processing** (`processFile`): If there are any errors while opening, scanning, or closing the file, they will be printed. If everything is fine, nothing is printed.
- **Mock closing** (`processCloserMock`): This will print `"close error"`, because the `Close()` method of `CloserMock` always returns that error.
- **Process with mock closing** (`processCloserMockWithError`): This will print:
  ```
  process error
  close error
  ```
  because `errors.New("process error")` is returned, and then the error from `CloserMock.Close()` is appended.

### 5. **Expected Output**

Given the code, the output will be something like:

```
open file: open /etc/hosts: no such file or directory
close error
process error
close error
```

- **First error**: For `processFile`, since `/etc/hosts` may not exist on your system, an error like `"open file: open /etc/hosts: no such file or directory"` will be printed.
- **Second error**: For `processCloserMock`, the `"close error"` from `CloserMock` will be printed.
- **Third error**: For `processCloserMockWithError`, both the `"process error"` and `"close error"` will be printed.

### 6. **Conclusion**

This program demonstrates how to:

- Use `multierr.AppendInvoke` and `multierr.Close` to manage multiple errors, especially in deferred function calls (like closing resources).
- Accumulate errors from multiple operations and return them together.
- Handle errors in a structured way without overwriting or losing any error details, which is important when working with resources that may fail at different stages of execution.
