The Go code you've provided demonstrates the use of **panic** and **recover** in Go. These are mechanisms to handle unexpected conditions in your code and allow you to regain control after a panic has occurred.

Let's break down the key concepts and explain the behavior step by step:

### Key Concepts

1. **`panic`**:
   - The `panic` function is used to terminate the normal flow of execution in a program. When `panic` is called, the current function stops executing immediately, and the control starts to "unwind" through the call stack (it starts running deferred functions in reverse order).
   - When `panic` is triggered, the program prints the error message and terminates unless it is **recovered**.

2. **`recover`**:
   - The `recover` function is used inside a deferred function to regain control after a panic. 
   - If a panic occurs, `recover` can catch the panic and prevent the program from crashing. If there is no panic, `recover` returns `nil`.
   - It must be called inside a `defer` statement to work properly.

### Code Explanation:

#### 1. **Main Function:**
```go
fmt.Println("before panic")
Catcher()
fmt.Println("after panic")
```
- The program first prints `before panic`, then it calls `Catcher()`, which is where the panic occurs. After the panic is caught by `recover`, the program prints `after panic`.

#### 2. **Panic Function:**
```go
func Panic() {
	zero, err := strconv.ParseInt("0", 10, 64)
	if err != nil {
		panic(err)
	}

	a := 1 / zero
	fmt.Println("we'll never get here", a)
}
```
- The `Panic` function is designed to create a panic scenario.
- First, it parses the string `"0"` into an integer `zero`. This succeeds because `"0"` is a valid integer.
- Then, the program attempts to perform a division by `zero` (`1 / zero`). Since `zero` is `0`, this will cause a **runtime error** due to division by zero, and the program will panic at this point.
- The line `fmt.Println("we'll never get here", a)` will **never** be reached because the program will panic before that.

#### 3. **Catcher Function:**
```go
func Catcher() {
	defer func() {
		if r := recover(); r != nil {
			fmt.Println("panic occurred:", r)
		}
	}()
	Panic()
}
```
- The `Catcher` function contains a `defer` statement with a function that checks for panics using `recover`.
- The `defer` function is executed after the `Panic()` function finishes (in this case, after it panics). The `recover` function is used to catch the panic that was triggered by the division by zero inside `Panic()`.
- If a panic occurs, `recover` captures the error and prevents the program from terminating. The error (the panic) is then printed by the `fmt.Println("panic occurred:", r)` statement inside the deferred function.
- **Note**: Without the `defer` and `recover`, the panic would cause the program to terminate immediately.

#### 4. **Program Flow:**
- **Step 1**: `main()` prints `"before panic"`.
- **Step 2**: `main()` calls `Catcher()`.
- **Step 3**: `Catcher()` calls `Panic()`.
- **Step 4**: `Panic()` causes a division by zero panic.
- **Step 5**: The panic triggers the `defer` function in `Catcher()`, and `recover` catches the panic.
- **Step 6**: The `recover` function prints the panic message: `"panic occurred: runtime error: integer divide by zero"`.
- **Step 7**: Control returns to `main()`, and the program continues execution, printing `"after panic"`.

### Output:

```plaintext
before panic
panic occurred: runtime error: integer divide by zero
after panic
```

- **"before panic"** is printed before the call to `Catcher()`.
- The panic occurs inside `Panic()`, but it is caught by `recover` inside the deferred function in `Catcher()`, so `"panic occurred: runtime error: integer divide by zero"` is printed.
- Finally, `"after panic"` is printed after the panic is handled.

### Key Rules:

1. **Panic Handling**:
   - `panic` is used to stop the normal execution flow of the program and trigger a "panic" scenario.
   - When a function panics, it stops executing immediately, and the program starts unwinding the call stack.

2. **Defer and Recover**:
   - The `defer` statement schedules a function to be executed when the surrounding function (`Catcher()`) returns.
   - `recover` can be used inside a deferred function to catch a panic and prevent the program from terminating unexpectedly.
   - If `recover` is not called, the panic will propagate up the call stack, and the program will terminate with an error.

3. **Panic Propagation**:
   - When a panic occurs, the program searches for a `defer` statement that can catch it using `recover`.
   - If `recover` is not found, the program will print the panic message and exit.

4. **Recovering from Panics**:
   - Using `recover` in a `defer` function ensures that the program can continue after a panic, allowing the program to handle errors gracefully.
   - In this case, `recover` prevents the program from crashing due to a division by zero and prints the panic message instead.

### Summary:
The code demonstrates how panics work in Go, how they can be caught with `recover` inside a `defer` block, and how the program can continue execution even after an error occurs. The key takeaway is that **`panic`** stops the program, but **`recover`** allows you to catch and handle that panic without crashing the program.